Workbook

Sheet Sommaire
A1: MODELES D'EVALUATION DES ACTIFS FINANCIERS & GESTION DE PORTEFEUILLES
A2: Universite Sorbonne Paris Nord | UFR SEG | M1 MBFA | Annee 2025-2026 | Prof. Nathalie Rey
A4: Indice de reference | C4: FTSE 100 (London Stock Exchange)
A5: Actif sans risque | C5: UK Gilt 10 ans — Rf = 1.4197% / an (moyenne 2013-2022)
A6: Taux de change | C6: EUR/GBP (cotations quotidiennes Refinitiv)
A7: Periode | C7: 02/01/2013 — 30/12/2022 (2 532 observations journalieres)
A8: Univers | C8: 10 actions du FTSE 100 cotees en GBP
A9: Date de remise | C9: Mi-avril 2026
A10: Auteurs | C10: Traore Sory Ibrahim | GMIRA Amine | BELLILI Ilian
A12: TABLE DES MATIERES
A13: INDICE | C13: Cotations quotidiennes FTSE 100 — evolution base 100 avec graphique
A14: ACTIONS | C14: Prix quotidiens des 10 titres du FTSE 100 (2013–2022)
A15: Obligations 10 ans | C15: UK Gilt & German Bund 10 ans — actif sans risque Rf
A16: Graphiques | C16: Evolution des cours en base 100 — toutes series + graphique
A17: TAUX DE CHANGE | C17: EUR/GBP — cotations et rendements log. avec graphique
A18: Statistiques | C18: Statistiques descriptives annualisees des rendements (formules)
A19: Rendements | C19: Rendements log. ri,t = LN(Pt/Pt-1) — formules inter-feuilles
A20: Markowitz | C20: Matrice Omega, matrice rho, poids MVP & Tangent, frontiere efficiente
A21: Sharpe | C21: Modele de marche : beta, alpha, V(ei), methode Elton-Gruber C*
A22: Regression DIAGEO | C22: Rapport OLS detaille — Diageo vs FTSE 100 avec graphique
A23: Regression GLENCORE | C23: Rapport OLS detaille — Glencore vs FTSE 100 avec graphique
A24: Performances | C24: Performances historiques MVP & Sharpe vs FTSE 100 + suivi
A27: RESULTATS CLES
A28: Portefeuille MVP (Markowitz) | C28: E(Rp) = 5.01% / an | sigma = 15.56% | Sharpe = 0.2306
A29: Portefeuille Tangent (max Sharpe MV) | C29: E(Rp) = 16.19% / an | sigma = 23.60% | Sharpe = 0.6259
A30: Portefeuille Optimal Sharpe (Elton-Gruber) | C30: E(Rp) = 14.95% / an | sigma = 21.92% | Sharpe = 0.6171
A31: Titres retenus — Portefeuille Sharpe | C31: Rentokil Initial (84.78%) + Diageo (15.22%)
A32: Seuil C* (Elton-Gruber) | C32: C* = 0.0535 — critere de selection des titres optimaux
A33: Variance de marche sigma2_M | C33: 0.000100 / jour = 2.5200% / an
A34: Taux sans risque Rf (annualise) | C34: 1.4197% / an (UK Gilt 10 ans, moyenne 2013-2022)
A35: Formules Excel | C35: Toutes les cellules contiennent de vraies formules (=LN, =COVAR, =VARP, =CORREL, =AVERAGE, =STDEV...)

Sheet INDICE
A1: Code RIC | C1: FTSE 100 - PRICE INDEX | D1: Base 100
A2: .FTSE | C2: CURRENCY (£) | D2: (P_t / P_0) x 100
C3: DATE | D3: FTSE 100 | E3: BASE 100
C4: 41277 | D4: 6047.34 | E4: 100
C5: 41278 | D5: 6089.84 | E5: =D5/$D$4*100 -> 100.70279
C6: 41281 | D6: 6064.58 | E6: =D6/$D$4*100 -> 100.28508
C7: 41282 | D7: 6053.63 | E7: =D7/$D$4*100 -> 100.10401
C8: 41283 | D8: 6098.65 | E8: =D8/$D$4*100 -> 100.84847
C9: 41284 | D9: 6101.51 | E9: =D9/$D$4*100 -> 100.89577
C10: 41285 | D10: 6121.58 | E10: =D10/$D$4*100 -> 101.22765
C11: 41288 | D11: 6107.86 | E11: =D11/$D$4*100 -> 101.00077
C12: 41289 | D12: 6117.31 | E12: =D12/$D$4*100 -> 101.15704
C13: 41290 | D13: 6103.98 | E13: =D13/$D$4*100 -> 100.93661
C14: 41291 | D14: 6132.36 | E14: =D14/$D$4*100 -> 101.40591
C15: 41292 | D15: 6154.41 | E15: =D15/$D$4*100 -> 101.77053
C16: 41295 | D16: 6180.98 | E16: =D16/$D$4*100 -> 102.2099
... C2535: 44925 | D2535: 7451.74 | E2535: =D2535/$D$4*100 -> 123.22343

Sheet ACTIONS
A1: Nom complet | B1: Code RIC | D1: NATWEST GROUP | E1: PHOENIX GROUP HDG. | F1: DIAGEO | G1: ASSOCIATED BRIT.FOODS | H1: IMPERIAL BRANDS | I1: ROLLS-ROYCE HOLDINGS | J1: RENTOKIL INITIAL | K1: GLENCORE | L1: BARRATT DEVELOPMENTS | M1: KINGFISHER
C2: CURRENCY | D2: £ | E2: £ | F2: £ | G2: £ | H2: £ | I2: £ | J2: £ | K2: £ | L2: £ | M2: £
A3: NATWEST GROUP | B3: NWG.L | C3: DATE | D3: NATWEST GROUP | E3: PHOENIX GROUP HDG. | F3: DIAGEO | G3: ASSOCIATED BRIT.FOODS | H3: IMPERIAL BRANDS | I3: ROLLS-ROYCE HOLDINGS | J3: RENTOKIL INITIAL | K3: GLENCORE | L3: BARRATT DEVELOPMENTS | M3: KINGFISHER
A4: PHOENIX GROUP HDG. | B4: PHNX.L | C4: 41277 | D4: 334 | E4: 417.56 | F4: 1818 | G4: 1573 | H4: 2412 | I4: 275.51 | J4: 96.7 | K4: 375.6 | L4: 209.3 | M4: 286.3
A5: DIAGEO | B5: DGE.L | C5: 41278 | D5: 335.41 | E5: 411.22 | F5: 1824.5 | G5: 1580 | H5: 2443 | I5: 277.32 | J5: 96.8 | K5: 378.88 | L5: 208.8 | M5: 287.7
A6: ASSOCIATED BRIT.FOODS | B6: ABF.L | C6: 41281 | D6: 335.51 | E6: 417.93 | F6: 1813 | G6: 1550 | H6: 2454 | I6: 273.25 | J6: 96.55 | K6: 377.84 | L6: 212.1 | M6: 286.3
A7: IMPERIAL BRANDS | B7: IMB.L | C7: 41282 | D7: 338.62 | E7: 415.32 | F7: 1804.5 | G7: 1550 | H7: 2473 | I7: 272.34 | J7: 94.85 | K7: 375.05 | L7: 215.9 | M7: 285
A8: ROLLS-ROYCE HOLDINGS | B8: RR.L | C8: 41283 | D8: 351.58 | E8: 422.4 | F8: 1798.5 | G8: 1546 | H8: 2469 | I8: 270.68 | J8: 94.4 | K8: 383.21 | L8: 217.7 | M8: 283.9
A9: RENTOKIL INITIAL | B9: RTO.L | C9: 41284 | D9: 358.52 | E9: 417.56 | F9: 1788 | G9: 1520 | H9: 2459 | I9: 269.17 | J9: 91.95 | K9: 384.95 | L9: 219.7 | M9: 283.3
A10: GLENCORE | B10: GLEN.L | C10: 41285 | D10: 362.13 | E10: 416.06 | F10: 1788.5 | G10: 1530 | H10: 2448 | I10: 269.02 | J10: 91.1 | K10: 389.53 | L10: 227.3 | M10: 285
A11: BARRATT DEVELOPMENTS | B11: BDEV.L | C11: 41288 | D11: 366.25 | E11: 420.91 | F11: 1788 | G11: 1500 | H11: 2470 | I11: 271.28 | J11: 91.3 | K11: 389.78 | L11: 225.1 | M11: 286.9
A12: KINGFISHER | B12: KGF.L | C12: 41289 | D12: 355.8 | E12: 421.28 | F12: 1802 | G12: 1532 | H12: 2484 | I12: 270.83 | J12: 90.6 | K12: 390.72 | L12: 226.5 | M12: 290
C13: 41290 | D13: 351.78 | E13: 421.28 | F13: 1806 | G13: 1556 | H13: 2368 | I13: 275.51 | J13: 90.35 | K13: 378.34 | L13: 224 | M13: 288.4
C14: 41291 | D14: 355.5 | E14: 423.89 | F14: 1824.5 | G14: 1606 | H14: 2363 | I14: 277.78 | J14: 90.3 | K14: 377.94 | L14: 225.7 | M14: 285.1
C15: 41292 | D15: 360.53 | E15: 425.01 | F15: 1843 | G15: 1635 | H15: 2378 | I15: 278.53 | J15: 90.65 | K15: 377.94 | L15: 231.1 | M15: 272.9
C16: 41295 | D16: 368.67 | E16: 437.31 | F16: 1819.5 | G16: 1629 | H16: 2394 | I16: 279.59 | J16: 90.8 | K16: 383.06 | L16: 230 | M16: 268.9
C17: 41296 | D17: 364.65 | E17: 430.23 | F17: 1836 | G17: 1646 | H17: 2388 | I17: 280.04 | J17: 90 | K17: 382.42 | L17: 226.6 | M17: 273
C18: 41297 | D18: 360.73 | E18: 423.52 | F18: 1865 | G18: 1669 | H18: 2385 | I18: 279.59 | J18: 88.7 | K18: 381.87 | L18: 218.4 | M18: 272.7
C19: 41298 | D19: 366.76 | E19: 436.2 | F19: 1860 | G19: 1675 | H19: 2390 | I19: 280.8 | J19: 90.2 | K19: 386.74 | L19: 222.7 | M19: 274.9
C20: 41299 | D20: 367.66 | E20: 435.08 | F20: 1857 | G20: 1708 | H20: 2420 | I20: 285.18 | J20: 90.65 | K20: 390.62 | L20: 226.1 | M20: 277.4
C21: 41302 | D21: 369.57 | E21: 436.57 | F21: 1859.5 | G21: 1715 | H21: 2423 | I21: 284.57 | J21: 90.75 | K21: 388.83 | L21: 223.6 | M21: 276.9
C22: 41303 | D22: 347.46 | E22: 440.67 | F22: 1872.5 | G22: 1735 | H22: 2466 | I22: 286.24 | J22: 90 | K22: 394.01 | L22: 224.1 | M22: 273
C23: 41304 | D23: 348.87 | E23: 481.84 | F23: 1853 | G23: 1745 | H23: 2361 | I23: 284.73 | J23: 89.45 | K23: 391.52 | L23: 219 | M23: 273.9
C24: 41305 | D24: 344.95 | E24: 489.49 | F24: 1877 | G24: 1749 | H24: 2345 | I24: 285.78 | J24: 89.25 | K24: 391.47 | L24: 217.6 | M24: 269.7
... C2535: 44925 | D2535: 265.2 | E2535: 608.6 | F2535: 3650 | G2535: 1576 | H2535: 2071 | I2535: 93.2 | J2535: 508 | K2535: 552.4 | L2535: 396.8 | M2535: 236.1

Sheet Obligations 10 ans
A1: RF GERMANY GVT BMK BID YLD 10Y - RED. YIELD | B1: RF UK GVT BMK BID YLD 10Y - RED. YIELD | C1: Rf quotidien = UK10Y / 100 / 252
A2: E (Allemagne) | B2: £ (Royaume-Uni) | C2: (actif sans risque journalier)
A3: DATE | B3: Germany 10Y (%) | C3: UK Gilt 10Y (%) | D3: Rf quotidien
A4: 41277 | B4: 1.441 | C4: 1.988 | D4: =C4/100/252 -> 7.8888889e-05
A5: 41278 | B5: 1.471 | C5: 2.073 | D5: =C5/100/252 -> 8.2261905e-05
A6: 41281 | B6: 1.544 | C6: 2.117 | D6: =C6/100/252 -> 8.4007937e-05
A7: 41282 | B7: 1.518 | C7: 2.086 | D7: =C7/100/252 -> 8.2777778e-05
A8: 41283 | B8: 1.49 | C8: 2.03 | D8: =C8/100/252 -> 8.0555556e-05
A9: 41284 | B9: 1.482 | C9: 2.024 | D9: =C9/100/252 -> 8.031746e-05
A10: 41285 | B10: 1.559 | C10: 2.096 | D10: =C10/100/252 -> 8.3174603e-05
A11: 41288 | B11: 1.584 | C11: 2.083 | D11: =C11/100/252 -> 8.265873e-05
A12: 41289 | B12: 1.552 | C12: 2.036 | D12: =C12/100/252 -> 8.0793651e-05
A13: 41290 | B13: 1.503 | C13: 2.023 | D13: =C13/100/252 -> 8.0277778e-05
A14: 41291 | B14: 1.501 | C14: 1.998 | D14: =C14/100/252 -> 7.9285714e-05
A15: 41292 | B15: 1.541 | C15: 2.04 | D15: =C15/100/252 -> 8.0952381e-05
... A2535: 44925 | B2535: 1.733 | C2535: 3.166 | D2535: =C2535/100/252 -> 0.00012563492

Sheet Graphiques
A1: DATE | B1: FTSE 100 | C1: NATWEST GROUP | D1: PHOENIX GROUP HDG. | E1: DIAGEO | F1: ASSOCIATED BRIT.FOODS | G1: IMPERIAL BRANDS | H1: ROLLS-ROYCE HOLDINGS | I1: RENTOKIL INITIAL | J1: GLENCORE | K1: BARRATT DEVELOPMENTS | L1: KINGFISHER
A2: 41277 | B2: =INDICE!D4/INDICE!$D$4*100 -> 100 | C2: =ACTIONS!D4/ACTIONS!$D$4*100 -> 100 | D2: =ACTIONS!E4/ACTIONS!$E$4*100 -> 100 | E2: =ACTIONS!F4/ACTIONS!$F$4*100 -> 100 | F2: =ACTIONS!G4/ACTIONS!$G$4*100 -> 100 | G2: =ACTIONS!H4/ACTIONS!$H$4*100 -> 100 | H2: =ACTIONS!I4/ACTIONS!$I$4*100 -> 100 | I2: =ACTIONS!J4/ACTIONS!$J$4*100 -> 100 | J2: =ACTIONS!K4/ACTIONS!$K$4*100 -> 100 | K2: =ACTIONS!L4/ACTIONS!$L$4*100 -> 100 | L2: =ACTIONS!M4/ACTIONS!$M$4*100 -> 100
A3: 41278 | B3: =INDICE!D5/INDICE!$D$4*100 -> 100.70279 | C3: =ACTIONS!D5/ACTIONS!$D$4*100 -> 100.42216 | D3: =ACTIONS!E5/ACTIONS!$E$4*100 -> 98.481655 | E3: =ACTIONS!F5/ACTIONS!$F$4*100 -> 100.35754 | F3: =ACTIONS!G5/ACTIONS!$G$4*100 -> 100.44501 | G3: =ACTIONS!H5/ACTIONS!$H$4*100 -> 101.28524 | H3: =ACTIONS!I5/ACTIONS!$I$4*100 -> 100.65696 | I3: =ACTIONS!J5/ACTIONS!$J$4*100 -> 100.10341 | J3: =ACTIONS!K5/ACTIONS!$K$4*100 -> 100.87327 | K3: =ACTIONS!L5/ACTIONS!$L$4*100 -> 99.761108 | L3: =ACTIONS!M5/ACTIONS!$M$4*100 -> 100.489
A4: 41281 | B4: =INDICE!D6/INDICE!$D$4*100 -> 100.28508 | C4: =ACTIONS!D6/ACTIONS!$D$4*100 -> 100.4521 | D4: =ACTIONS!E6/ACTIONS!$E$4*100 -> 100.08861 | E4: =ACTIONS!F6/ACTIONS!$F$4*100 -> 99.724972 | F4: =ACTIONS!G6/ACTIONS!$G$4*100 -> 98.537826 | G4: =ACTIONS!H6/ACTIONS!$H$4*100 -> 101.74129 | H4: =ACTIONS!I6/ACTIONS!$I$4*100 -> 99.179703 | I4: =ACTIONS!J6/ACTIONS!$J$4*100 -> 99.844881 | J4: =ACTIONS!K6/ACTIONS!$K$4*100 -> 100.59638 | K4: =ACTIONS!L6/ACTIONS!$L$4*100 -> 101.33779 | L4: =ACTIONS!M6/ACTIONS!$M$4*100 -> 100
A5: 41282 | B5: =INDICE!D7/INDICE!$D$4*100 -> 100.10401 | C5: =ACTIONS!D7/ACTIONS!$D$4*100 -> 101.38323 | D5: =ACTIONS!E7/ACTIONS!$E$4*100 -> 99.46355 | E5: =ACTIONS!F7/ACTIONS!$F$4*100 -> 99.257426 | F5: =ACTIONS!G7/ACTIONS!$G$4*100 -> 98.537826 | G5: =ACTIONS!H7/ACTIONS!$H$4*100 -> 102.52902 | H5: =ACTIONS!I7/ACTIONS!$I$4*100 -> 98.849407 | I5: =ACTIONS!J7/ACTIONS!$J$4*100 -> 98.086867 | J5: =ACTIONS!K7/ACTIONS!$K$4*100 -> 99.853568 | K5: =ACTIONS!L7/ACTIONS!$L$4*100 -> 103.15337 | L5: =ACTIONS!M7/ACTIONS!$M$4*100 -> 99.545931
A6: 41283 | B6: =INDICE!D8/INDICE!$D$4*100 -> 100.84847 | C6: =ACTIONS!D8/ACTIONS!$D$4*100 -> 105.26347 | D6: =ACTIONS!E8/ACTIONS!$E$4*100 -> 101.15911 | E6: =ACTIONS!F8/ACTIONS!$F$4*100 -> 98.927393 | F6: =ACTIONS!G8/ACTIONS!$G$4*100 -> 98.283535 | G6: =ACTIONS!H8/ACTIONS!$H$4*100 -> 102.36318 | H6: =ACTIONS!I8/ACTIONS!$I$4*100 -> 98.246888 | I6: =ACTIONS!J8/ACTIONS!$J$4*100 -> 97.62151 | J6: =ACTIONS!K8/ACTIONS!$K$4*100 -> 102.02609 | K6: =ACTIONS!L8/ACTIONS!$L$4*100 -> 104.01338 | L6: =ACTIONS!M8/ACTIONS!$M$4*100 -> 99.161718
A7: 41284 | B7: =INDICE!D9/INDICE!$D$4*100 -> 100.89577 | C7: =ACTIONS!D9/ACTIONS!$D$4*100 -> 107.34132 | D7: =ACTIONS!E9/ACTIONS!$E$4*100 -> 100 | E7: =ACTIONS!F9/ACTIONS!$F$4*100 -> 98.349835 | F7: =ACTIONS!G9/ACTIONS!$G$4*100 -> 96.630642 | G7: =ACTIONS!H9/ACTIONS!$H$4*100 -> 101.94859 | H7: =ACTIONS!I9/ACTIONS!$I$4*100 -> 97.698813 | I7: =ACTIONS!J9/ACTIONS!$J$4*100 -> 95.087901 | J7: =ACTIONS!K9/ACTIONS!$K$4*100 -> 102.48935 | K7: =ACTIONS!L9/ACTIONS!$L$4*100 -> 104.96894 | L7: =ACTIONS!M9/ACTIONS!$M$4*100 -> 98.952148
A8: 41285 | B8: =INDICE!D10/INDICE!$D$4*100 -> 101.22765 | C8: =ACTIONS!D10/ACTIONS!$D$4*100 -> 108.42216 | D8: =ACTIONS!E10/ACTIONS!$E$4*100 -> 99.64077 | E8: =ACTIONS!F10/ACTIONS!$F$4*100 -> 98.377338 | F8: =ACTIONS!G10/ACTIONS!$G$4*100 -> 97.26637 | G8: =ACTIONS!H10/ACTIONS!$H$4*100 -> 101.49254 | H8: =ACTIONS!I10/ACTIONS!$I$4*100 -> 97.644369 | I8: =ACTIONS!J10/ACTIONS!$J$4*100 -> 94.208893 | J8: =ACTIONS!K10/ACTIONS!$K$4*100 -> 103.70873 | K8: =ACTIONS!L10/ACTIONS!$L$4*100 -> 108.6001 | L8: =ACTIONS!M10/ACTIONS!$M$4*100 -> 99.545931
A9: 41288 | B9: =INDICE!D11/INDICE!$D$4*100 -> 101.00077 | C9: =ACTIONS!D11/ACTIONS!$D$4*100 -> 109.65569 | D9: =ACTIONS!E11/ACTIONS!$E$4*100 -> 100.80228 | E9: =ACTIONS!F11/ACTIONS!$F$4*100 -> 98.349835 | F9: =ACTIONS!G11/ACTIONS!$G$4*100 -> 95.359186 | G9: =ACTIONS!H11/ACTIONS!$H$4*100 -> 102.40464 | H9: =ACTIONS!I11/ACTIONS!$I$4*100 -> 98.464666 | I9: =ACTIONS!J11/ACTIONS!$J$4*100 -> 94.415719 | J9: =ACTIONS!K11/ACTIONS!$K$4*100 -> 103.77529 | K9: =ACTIONS!L11/ACTIONS!$L$4*100 -> 107.54897 | L9: =ACTIONS!M11/ACTIONS!$M$4*100 -> 100.20957
A10: 41289 | B10: =INDICE!D12/INDICE!$D$4*100 -> 101.15704 | C10: =ACTIONS!D12/ACTIONS!$D$4*100 -> 106.52695 | D10: =ACTIONS!E12/ACTIONS!$E$4*100 -> 100.89089 | E10: =ACTIONS!F12/ACTIONS!$F$4*100 -> 99.119912 | F10: =ACTIONS!G12/ACTIONS!$G$4*100 -> 97.393516 | G10: =ACTIONS!H12/ACTIONS!$H$4*100 -> 102.98507 | H10: =ACTIONS!I12/ACTIONS!$I$4*100 -> 98.301332 | I10: =ACTIONS!J12/ACTIONS!$J$4*100 -> 93.69183 | J10: =ACTIONS!K12/ACTIONS!$K$4*100 -> 104.02556 | K10: =ACTIONS!L12/ACTIONS!$L$4*100 -> 108.21787 | L10: =ACTIONS!M12/ACTIONS!$M$4*100 -> 101.29235
A11: 41290 | B11: =INDICE!D13/INDICE!$D$4*100 -> 100.93661 | C11: =ACTIONS!D13/ACTIONS!$D$4*100 -> 105.32335 | D11: =ACTIONS!E13/ACTIONS!$E$4*100 -> 100.89089 | E11: =ACTIONS!F13/ACTIONS!$F$4*100 -> 99.339934 | F11: =ACTIONS!G13/ACTIONS!$G$4*100 -> 98.919263 | G11: =ACTIONS!H13/ACTIONS!$H$4*100 -> 98.175788 | H11: =ACTIONS!I13/ACTIONS!$I$4*100 -> 100 | I11: =ACTIONS!J13/ACTIONS!$J$4*100 -> 93.433299 | J11: =ACTIONS!K13/ACTIONS!$K$4*100 -> 100.7295 | K11: =ACTIONS!L13/ACTIONS!$L$4*100 -> 107.02341 | L11: =ACTIONS!M13/ACTIONS!$M$4*100 -> 100.7335
A12: 41291 | B12: =INDICE!D14/INDICE!$D$4*100 -> 101.40591 | C12: =ACTIONS!D14/ACTIONS!$D$4*100 -> 106.43713 | D12: =ACTIONS!E14/ACTIONS!$E$4*100 -> 101.51595 | E12: =ACTIONS!F14/ACTIONS!$F$4*100 -> 100.35754 | F12: =ACTIONS!G14/ACTIONS!$G$4*100 -> 102.0979 | G12: =ACTIONS!H14/ACTIONS!$H$4*100 -> 97.968491 | H12: =ACTIONS!I14/ACTIONS!$I$4*100 -> 100.82393 | I12: =ACTIONS!J14/ACTIONS!$J$4*100 -> 93.381593 | J12: =ACTIONS!K14/ACTIONS!$K$4*100 -> 100.623 | K12: =ACTIONS!L14/ACTIONS!$L$4*100 -> 107.83564 | L12: =ACTIONS!M14/ACTIONS!$M$4*100 -> 99.580859
A13: 41292 | B13: =INDICE!D15/INDICE!$D$4*100 -> 101.77053 | C13: =ACTIONS!D15/ACTIONS!$D$4*100 -> 107.94311 | D13: =ACTIONS!E15/ACTIONS!$E$4*100 -> 101.78417 | E13: =ACTIONS!F15/ACTIONS!$F$4*100 -> 101.37514 | F13: =ACTIONS!G15/ACTIONS!$G$4*100 -> 103.94151 | G13: =ACTIONS!H15/ACTIONS!$H$4*100 -> 98.590381 | H13: =ACTIONS!I15/ACTIONS!$I$4*100 -> 101.09615 | I13: =ACTIONS!J15/ACTIONS!$J$4*100 -> 93.743537 | J13: =ACTIONS!K15/ACTIONS!$K$4*100 -> 100.623 | K13: =ACTIONS!L15/ACTIONS!$L$4*100 -> 110.41567 | L13: =ACTIONS!M15/ACTIONS!$M$4*100 -> 95.319595
... A2533: 44925 | B2533: =INDICE!D2535/INDICE!$D$4*100 -> 123.22343 | C2533: =ACTIONS!D2535/ACTIONS!$D$4*100 -> 79.401198 | D2533: =ACTIONS!E2535/ACTIONS!$E$4*100 -> 145.75151 | E2533: =ACTIONS!F2535/ACTIONS!$F$4*100 -> 200.77008 | F2533: =ACTIONS!G2535/ACTIONS!$G$4*100 -> 100.19072 | G2533: =ACTIONS!H2535/ACTIONS!$H$4*100 -> 85.862355 | H2533: =ACTIONS!I2535/ACTIONS!$I$4*100 -> 33.828173 | I2533: =ACTIONS!J2535/ACTIONS!$J$4*100 -> 525.33609 | J2533: =ACTIONS!K2535/ACTIONS!$K$4*100 -> 147.07135 | K2533: =ACTIONS!L2535/ACTIONS!$L$4*100 -> 189.58433 | L2533: =ACTIONS!M2535/ACTIONS!$M$4*100 -> 82.465945

Sheet TAUX DE CHANGE
A1: Code RIC | B1: EURGBP=R
A2: GBP TO EURO (RFV) - EXCHANGE RATE
B3: CURRENCY | C3: E | D3: DATE | E3: EUR/GBP | F3: Rendement log. ri,t = ln(Pt/Pt-1)
D4: 41277 | E4: 0.81125
D5: 41278 | E5: 0.8105 | F5: =LN(E5/E4) -> -0.00092492684
D6: 41281 | E6: 0.8135 | F6: =LN(E6/E5) -> 0.0036945855
D7: 41282 | E7: 0.8138 | F7: =LN(E7/E6) -> 0.00036870891
D8: 41283 | E8: 0.8149 | F8: =LN(E8/E7) -> 0.0013507708
D9: 41284 | E9: 0.81515 | F9: =LN(E9/E8) -> 0.00030673906
D10: 41285 | E10: 0.8208 | F10: =LN(E10/E9) -> 0.006907329
D11: 41288 | E11: 0.8273 | F11: =LN(E11/E10) -> 0.0078879118
D12: 41289 | E12: 0.832 | F12: =LN(E12/E11) -> 0.0056650546
D13: 41290 | E13: 0.8282 | F13: =LN(E13/E12) -> -0.0045777697
D14: 41291 | E14: 0.8303 | F14: =LN(E14/E13) -> 0.0025324102
D15: 41292 | E15: 0.836 | F15: =LN(E15/E14) -> 0.0068415318
D16: 41295 | E16: 0.839 | F16: =LN(E16/E15) -> 0.0035820934
... D2535: 44925 | E2535: 0.8723 | F2535: =LN(E2535/E2534) -> 0.0079993521

Sheet Statistiques
A1: NATWEST GROUP | C1: PHOENIX GROUP HDG. | E1: DIAGEO | G1: ASSOCIATED BRIT.FOODS | I1: IMPERIAL BRANDS | K1: ROLLS-ROYCE HOLDINGS | M1: RENTOKIL INITIAL | O1: GLENCORE | Q1: BARRATT DEVELOPMENTS | S1: KINGFISHER
B2: =STDEV(Rendements!B2:B2533) -> 0.021891532 | D2: =STDEV(Rendements!C2:C2533) -> 0.015730337 | F2: =STDEV(Rendements!D2:D2533) -> 0.012844756 | H2: =STDEV(Rendements!E2:E2533) -> 0.017538009 | J2: =STDEV(Rendements!F2:F2533) -> 0.014827062 | L2: =STDEV(Rendements!G2:G2533) -> 0.02871674 | N2: =STDEV(Rendements!H2:H2533) -> 0.015198299 | P2: =STDEV(Rendements!I2:I2533) -> 0.027588652 | R2: =STDEV(Rendements!J2:J2533) -> 0.023006485 | T2: =STDEV(Rendements!K2:K2533) -> 0.019105062
A3: Moyenne | B3: =AVERAGE(Rendements!B2:B2533) -> -9.1132649e-05 | C3: Moyenne | D3: =AVERAGE(Rendements!C2:C2533) -> 0.00014884749 | E3: Moyenne | F3: =AVERAGE(Rendements!D2:D2533) -> 0.00027538134 | G3: Moyenne | H3: =AVERAGE(Rendements!E2:E2533) -> 7.5281207e-07 | I3: Moyenne | J3: =AVERAGE(Rendements!F2:F2533) -> -6.0223112e-05 | K3: Moyenne | L3: =AVERAGE(Rendements!G2:G2533) -> -0.0004282403 | M3: Moyenne | N3: =AVERAGE(Rendements!H2:H2533) -> 0.00065542001 | O3: Moyenne | P3: =AVERAGE(Rendements!I2:I2533) -> 0.0001524092 | Q3: Moyenne | R3: =AVERAGE(Rendements!J2:J2533) -> 0.00025273163 | S3: Moyenne | T3: =AVERAGE(Rendements!K2:K2533) -> -7.6169407e-05
A4: Erreur-type | B4: =STDEV(Rendements!B2:B2533)/SQRT(2532) -> 0.00043505514 | C4: Erreur-type | D4: =STDEV(Rendements!C2:C2533)/SQRT(2532) -> 0.00031261239 | E4: Erreur-type | F4: =STDEV(Rendements!D2:D2533)/SQRT(2532) -> 0.00025526661 | G4: Erreur-type | H4: =STDEV(Rendements!E2:E2533)/SQRT(2532) -> 0.00034853663 | I4: Erreur-type | J4: =STDEV(Rendements!F2:F2533)/SQRT(2532) -> 0.00029466141 | K4: Erreur-type | L4: =STDEV(Rendements!G2:G2533)/SQRT(2532) -> 0.00057069397 | M4: Erreur-type | N4: =STDEV(Rendements!H2:H2533)/SQRT(2532) -> 0.00030203908 | O4: Erreur-type | P4: =STDEV(Rendements!I2:I2533)/SQRT(2532) -> 0.00054827523 | Q4: Erreur-type | R4: =STDEV(Rendements!J2:J2533)/SQRT(2532) -> 0.00045721285 | S4: Erreur-type | T4: =STDEV(Rendements!K2:K2533)/SQRT(2532) -> 0.00037967902
A5: Médiane | B5: =MEDIAN(Rendements!B2:B2533) -> 0 | C5: Médiane | D5: =MEDIAN(Rendements!C2:C2533) -> 0 | E5: Médiane | F5: =MEDIAN(Rendements!D2:D2533) -> 0.00024996876 | G5: Médiane | H5: =MEDIAN(Rendements!E2:E2533) -> 0 | I5: Médiane | J5: =MEDIAN(Rendements!F2:F2533) -> 0.00035011963 | K5: Médiane | L5: =MEDIAN(Rendements!G2:G2533) -> 0 | M5: Médiane | N5: =MEDIAN(Rendements!H2:H2533) -> 0.00041937514 | O5: Médiane | P5: =MEDIAN(Rendements!I2:I2533) -> 0.00061155847 | Q5: Médiane | R5: =MEDIAN(Rendements!J2:J2533) -> 0.00082610496 | S5: Médiane | T5: =MEDIAN(Rendements!K2:K2533) -> 0
A6: Mode | B6: =0 -> 0 | C6: Mode | D6: =0 -> 0 | E6: Mode | F6: =0 -> 0 | G6: Mode | H6: =0 -> 0 | I6: Mode | J6: =0 -> 0 | K6: Mode | L6: =0 -> 0 | M6: Mode | N6: =0 -> 0 | O6: Mode | P6: =0 -> 0 | Q6: Mode | R6: =0 -> 0 | S6: Mode | T6: =0 -> 0
A7: Écart-type | B7: =STDEV(Rendements!B2:B2533) -> 0.021891532 | C7: Écart-type | D7: =STDEV(Rendements!C2:C2533) -> 0.015730337 | E7: Écart-type | F7: =STDEV(Rendements!D2:D2533) -> 0.012844756 | G7: Écart-type | H7: =STDEV(Rendements!E2:E2533) -> 0.017538009 | I7: Écart-type | J7: =STDEV(Rendements!F2:F2533) -> 0.014827062 | K7: Écart-type | L7: =STDEV(Rendements!G2:G2533) -> 0.02871674 | M7: Écart-type | N7: =STDEV(Rendements!H2:H2533) -> 0.015198299 | O7: Écart-type | P7: =STDEV(Rendements!I2:I2533) -> 0.027588652 | Q7: Écart-type | R7: =STDEV(Rendements!J2:J2533) -> 0.023006485 | S7: Écart-type | T7: =STDEV(Rendements!K2:K2533) -> 0.019105062
A8: Variance de l'échantillon | B8: =VAR(Rendements!B2:B2533) -> 0.00047923917 | C8: Variance de l'échantillon | D8: =VAR(Rendements!C2:C2533) -> 0.00024744352 | E8: Variance de l'échantillon | F8: =VAR(Rendements!D2:D2533) -> 0.00016498776 | G8: Variance de l'échantillon | H8: =VAR(Rendements!E2:E2533) -> 0.00030758175 | I8: Variance de l'échantillon | J8: =VAR(Rendements!F2:F2533) -> 0.00021984177 | K8: Variance de l'échantillon | L8: =VAR(Rendements!G2:G2533) -> 0.00082465116 | M8: Variance de l'échantillon | N8: =VAR(Rendements!H2:H2533) -> 0.0002309883 | O8: Variance de l'échantillon | P8: =VAR(Rendements!I2:I2533) -> 0.00076113371 | Q8: Variance de l'échantillon | R8: =VAR(Rendements!J2:J2533) -> 0.00052929836 | S8: Variance de l'échantillon | T8: =VAR(Rendements!K2:K2533) -> 0.00036500339
A9: Kurstosis (Coefficient d'aplatissement) | B9: =KURT(Rendements!B2:B2533) -> 7.1613509 | C9: Kurstosis (Coefficient d'aplatissement) | D9: =KURT(Rendements!C2:C2533) -> 15.072076 | E9: Kurstosis (Coefficient d'aplatissement) | F9: =KURT(Rendements!D2:D2533) -> 6.1665024 | G9: Kurstosis (Coefficient d'aplatissement) | H9: =KURT(Rendements!E2:E2533) -> 11.048716 | I9: Kurstosis (Coefficient d'aplatissement) | J9: =KURT(Rendements!F2:F2533) -> 7.2120291 | K9: Kurstosis (Coefficient d'aplatissement) | L9: =KURT(Rendements!G2:G2533) -> 19.338494 | M9: Kurstosis (Coefficient d'aplatissement) | N9: =KURT(Rendements!H2:H2533) -> 11.94688 | O9: Kurstosis (Coefficient d'aplatissement) | P9: =KURT(Rendements!I2:I2533) -> 15.578739 | Q9: Kurstosis (Coefficient d'aplatissement) | R9: =KURT(Rendements!J2:J2533) -> 15.849815 | S9: Kurstosis (Coefficient d'aplatissement) | T9: =KURT(Rendements!K2:K2533) -> 7.7170858
A10: Coefficient d'asymétrie | B10: =SKEW(Rendements!B2:B2533) -> -0.53034046 | C10: Coefficient d'asymétrie | D10: =SKEW(Rendements!C2:C2533) -> -0.11157158 | E10: Coefficient d'asymétrie | F10: =SKEW(Rendements!D2:D2533) -> 0.08897046 | G10: Coefficient d'asymétrie | H10: =SKEW(Rendements!E2:E2533) -> 0.18284135 | I10: Coefficient d'asymétrie | J10: =SKEW(Rendements!F2:F2533) -> -0.48567359 | K10: Coefficient d'asymétrie | L10: =SKEW(Rendements!G2:G2533) -> 0.75887659 | M10: Coefficient d'asymétrie | N10: =SKEW(Rendements!H2:H2533) -> -0.12904683 | O10: Coefficient d'asymétrie | P10: =SKEW(Rendements!I2:I2533) -> -0.84690651 | Q10: Coefficient d'asymétrie | R10: =SKEW(Rendements!J2:J2533) -> -1.2049913 | S10: Coefficient d'asymétrie | T10: =SKEW(Rendements!K2:K2533) -> -0.35806862
A11: Plage | B11: =MAX(Rendements!B2:B2533)-MIN(Rendements!B2:B2533) -> 0.32757924 | C11: Plage | D11: =MAX(Rendements!C2:C2533)-MIN(Rendements!C2:C2533) -> 0.30201992 | E11: Plage | F11: =MAX(Rendements!D2:D2533)-MIN(Rendements!D2:D2533) -> 0.18479649 | G11: Plage | H11: =MAX(Rendements!E2:E2533)-MIN(Rendements!E2:E2533) -> 0.33554466 | I11: Plage | J11: =MAX(Rendements!F2:F2533)-MIN(Rendements!F2:F2533) -> 0.25448362 | K11: Plage | L11: =MAX(Rendements!G2:G2533)-MIN(Rendements!G2:G2533) -> 0.58069772 | M11: Plage | N11: =MAX(Rendements!H2:H2533)-MIN(Rendements!H2:H2533) -> 0.29222017 | O11: Plage | P11: =MAX(Rendements!I2:I2533)-MIN(Rendements!I2:I2533) -> 0.53944765 | Q11: Plage | R11: =MAX(Rendements!J2:J2533)-MIN(Rendements!J2:J2533) -> 0.42441792 | S11: Plage | T11: =MAX(Rendements!K2:K2533)-MIN(Rendements!K2:K2533) -> 0.2973218
A12: Minimum | B12: =MIN(Rendements!B2:B2533) -> -0.19899469 | C12: Minimum | D12: =MIN(Rendements!C2:C2533) -> -0.12584981 | E12: Minimum | F12: =MIN(Rendements!D2:D2533) -> -0.090932546 | G12: Minimum | H12: =MIN(Rendements!E2:E2533) -> -0.16623542 | I12: Minimum | J12: =MIN(Rendements!F2:F2533) -> -0.13858616 | K12: Minimum | L12: =MIN(Rendements!G2:G2533) -> -0.21771723 | M12: Minimum | N12: =MIN(Rendements!H2:H2533) -> -0.1312461 | O12: Minimum | P12: =MIN(Rendements!I2:I2533) -> -0.34839241 | Q12: Minimum | R12: =MIN(Rendements!J2:J2533) -> -0.27238836 | S12: Minimum | T12: =MIN(Rendements!K2:K2533) -> -0.16090696
A13: Maximum | B13: =MAX(Rendements!B2:B2533) -> 0.12858456 | C13: Maximum | D13: =MAX(Rendements!C2:C2533) -> 0.17617011 | E13: Maximum | F13: =MAX(Rendements!D2:D2533) -> 0.093863948 | G13: Maximum | H13: =MAX(Rendements!E2:E2533) -> 0.16930924 | I13: Maximum | J13: =MAX(Rendements!F2:F2533) -> 0.11589745 | K13: Maximum | L13: =MAX(Rendements!G2:G2533) -> 0.3629805 | M13: Maximum | N13: =MAX(Rendements!H2:H2533) -> 0.16097407 | O13: Maximum | P13: =MAX(Rendements!I2:I2533) -> 0.19105524 | Q13: Maximum | R13: =MAX(Rendements!J2:J2533) -> 0.15202955 | S13: Maximum | T13: =MAX(Rendements!K2:K2533) -> 0.13641484
A14: Somme | B14: =SUM(Rendements!B2:B2533) -> -0.23065673 | C14: Somme | D14: =SUM(Rendements!C2:C2533) -> 0.37673299 | E14: Somme | F14: =SUM(Rendements!D2:D2533) -> 0.69699017 | G14: Somme | H14: =SUM(Rendements!E2:E2533) -> 0.0019053674 | I14: Somme | J14: =SUM(Rendements!F2:F2533) -> -0.1524247 | K14: Somme | L14: =SUM(Rendements!G2:G2533) -> -1.0838762 | M14: Somme | N14: =SUM(Rendements!H2:H2533) -> 1.658868 | O14: Somme | P14: =SUM(Rendements!I2:I2533) -> 0.38574767 | Q14: Somme | R14: =SUM(Rendements!J2:J2533) -> 0.63966375 | S14: Somme | T14: =SUM(Rendements!K2:K2533) -> -0.19278477
A15: Nombre d'échantillons | B15: =COUNT(Rendements!B2:B2533) -> 2531 | C15: Nombre d'échantillons | D15: =COUNT(Rendements!C2:C2533) -> 2531 | E15: Nombre d'échantillons | F15: =COUNT(Rendements!D2:D2533) -> 2531 | G15: Nombre d'échantillons | H15: =COUNT(Rendements!E2:E2533) -> 2531 | I15: Nombre d'échantillons | J15: =COUNT(Rendements!F2:F2533) -> 2531 | K15: Nombre d'échantillons | L15: =COUNT(Rendements!G2:G2533) -> 2531 | M15: Nombre d'échantillons | N15: =COUNT(Rendements!H2:H2533) -> 2531 | O15: Nombre d'échantillons | P15: =COUNT(Rendements!I2:I2533) -> 2531 | Q15: Nombre d'échantillons | R15: =COUNT(Rendements!J2:J2533) -> 2531 | S15: Nombre d'échantillons | T15: =COUNT(Rendements!K2:K2533) -> 2531

Sheet Rendements
A1: Date | B1: NATWEST GROUP | C1: PHOENIX GROUP HDG. | D1: DIAGEO | E1: ASSOCIATED BRIT.FOODS | F1: IMPERIAL BRANDS | G1: ROLLS-ROYCE HOLDINGS | H1: RENTOKIL INITIAL | I1: GLENCORE | J1: BARRATT DEVELOPMENTS | K1: KINGFISHER | L1: FTSE 100 | N1: NATWEST GROUP | O1: PHOENIX GROUP HDG. | P1: DIAGEO | Q1: ASSOCIATED BRIT.FOODS | R1: IMPERIAL BRANDS | S1: ROLLS-ROYCE HOLDINGS | T1: RENTOKIL INITIAL | U1: GLENCORE | V1: BARRATT DEVELOPMENTS | W1: KINGFISHER | X1: FTSE 100
A2: 41277 | M2: E(Ri) = | N2: =AVERAGE(B2:B2533) -> -9.1132649e-05 | O2: =AVERAGE(C2:C2533) -> 0.00014884749 | P2: =AVERAGE(D2:D2533) -> 0.00027538134 | Q2: =AVERAGE(E2:E2533) -> 7.5281207e-07 | R2: =AVERAGE(F2:F2533) -> -6.0223112e-05 | S2: =AVERAGE(G2:G2533) -> -0.0004282403 | T2: =AVERAGE(H2:H2533) -> 0.00065542001 | U2: =AVERAGE(I2:I2533) -> 0.0001524092 | ... X2: =AVERAGE(L2:L2533) -> 8.2508517e-05
A3: 41278 | B3: =LN(ACTIONS!D5/ACTIONS!D4) -> 0.0042126711 | C3: =LN(ACTIONS!E5/ACTIONS!E4) -> -0.015299895 | D3: =LN(ACTIONS!F5/ACTIONS!F4) -> 0.0035689811 | E3: =LN(ACTIONS!G5/ACTIONS!G4) -> 0.004440223 | F3: =LN(ACTIONS!H5/ACTIONS!H4) -> 0.012770513 | G3: =LN(ACTIONS!I5/ACTIONS!I4) -> 0.0065481485 | H3: =LN(ACTIONS!J5/ACTIONS!J4) -> 0.0010335918 | I3: =LN(ACTIONS!K5/ACTIONS!K4) -> 0.0086947849 | ... K3: =LN(ACTIONS!M5/ACTIONS!M4) -> 0.0048780585 | L3: =LN(INDICE!D5/INDICE!D4) -> 0.0070033029 | M3: E(Ri) annuel= | N3: =AVERAGE(B2:B2533)*252 -> -0.022965428 | O3: =AVERAGE(C2:C2533)*252 -> 0.037509567 | P3: =AVERAGE(D2:D2533)*252 -> 0.069396098 | Q3: =AVERAGE(E2:E2533)*252 -> 0.00018970864 | R3: =AVERAGE(F2:F2533)*252 -> -0.015176224 | S3: =AVERAGE(G2:G2533)*252 -> -0.10791656 | T3: =AVERAGE(H2:H2533)*252 -> 0.16516584 | U3: =AVERAGE(I2:I2533)*252 -> 0.038407117 | ... X3: =AVERAGE(L2:L2533)*252 -> 0.020792146
A4: 41281 | B4: =LN(ACTIONS!D6/ACTIONS!D5) -> 0.00029809814 | C4: =LN(ACTIONS!E6/ACTIONS!E5) -> 0.016185603 | D4: =LN(ACTIONS!F6/ACTIONS!F5) -> -0.0063230451 | E4: =LN(ACTIONS!G6/ACTIONS!G5) -> -0.019169916 | F4: =LN(ACTIONS!H6/ACTIONS!H5) -> 0.004492554 | G4: =LN(ACTIONS!I6/ACTIONS!I5) -> -0.014784947 | H4: =LN(ACTIONS!J6/ACTIONS!J5) -> -0.0025859854 | I4: =LN(ACTIONS!K6/ACTIONS!K5) -> -0.0027487067 | ... K4: =LN(ACTIONS!M6/ACTIONS!M5) -> -0.0048780585 | L4: =LN(INDICE!D6/INDICE!D5) -> -0.0041565186 | M4: sigma(Ri) = | N4: =STDEV(B2:B2533) -> 0.021891532 | O4: =STDEV(C2:C2533) -> 0.015730337 | P4: =STDEV(D2:D2533) -> 0.012844756 | Q4: =STDEV(E2:E2533) -> 0.017538009 | R4: =STDEV(F2:F2533) -> 0.014827062 | S4: =STDEV(G2:G2533) -> 0.02871674 | T4: =STDEV(H2:H2533) -> 0.015198299 | U4: =STDEV(I2:I2533) -> 0.027588652 | ... X4: =STDEV(L2:L2533) -> 0.010008307
A5: 41282 | B5: =LN(ACTIONS!D7/ACTIONS!D6) -> 0.0092267725 | C5: =LN(ACTIONS!E7/ACTIONS!E6) -> -0.006264647 | D5: =LN(ACTIONS!F7/ACTIONS!F6) -> -0.0046993867 | E5: =LN(ACTIONS!G7/ACTIONS!G6) -> 0 | F5: =LN(ACTIONS!H7/ACTIONS!H6) -> 0.0077126423 | G5: =LN(ACTIONS!I7/ACTIONS!I6) -> -0.0033358414 | H5: =LN(ACTIONS!J7/ACTIONS!J6) -> -0.017764312 | I5: =LN(ACTIONS!K7/ACTIONS!K6) -> -0.0074114752 | ... K5: =LN(ACTIONS!M7/ACTIONS!M6) -> -0.0045510318 | L5: =LN(INDICE!D7/INDICE!D6) -> -0.0018071981 | M5: sigma(Ri) annuel = | N5: =STDEV(B2:B2533)*SQRT(252) -> 0.3475173 | O5: =STDEV(C2:C2533)*SQRT(252) -> 0.24971137 | P5: =STDEV(D2:D2533)*SQRT(252) -> 0.20390418 | Q5: =STDEV(E2:E2533)*SQRT(252) -> 0.27840726 | R5: =STDEV(F2:F2533)*SQRT(252) -> 0.23537232 | S5: =STDEV(G2:G2533)*SQRT(252) -> 0.45586411 | T5: =STDEV(H2:H2533)*SQRT(252) -> 0.24126552 | U5: =STDEV(I2:I2533)*SQRT(252) -> 0.43795627 | ... X5: =STDEV(L2:L2533)*SQRT(252) -> 0.15887695
A6: 41283 | B6: =LN(ACTIONS!D8/ACTIONS!D7) -> 0.037558747 | C6: =LN(ACTIONS!E8/ACTIONS!E7) -> 0.016903425 | D6: =LN(ACTIONS!F8/ACTIONS!F7) -> -0.0033305609 | E6: =LN(ACTIONS!G8/ACTIONS!G7) -> -0.0025839808 | F6: =LN(ACTIONS!H8/ACTIONS!H7) -> -0.0016187782 | G6: =LN(ACTIONS!I8/ACTIONS!I7) -> -0.0061139743 | H6: =LN(ACTIONS!J8/ACTIONS!J7) -> -0.0047556232 | I6: =LN(ACTIONS!K8/ACTIONS!K7) -> 0.021523791 | ... K6: =LN(ACTIONS!M8/ACTIONS!M7) -> -0.0038671168 | L6: =LN(INDICE!D8/INDICE!D7) -> 0.0074093431
A7: 41284 | B7: =LN(ACTIONS!D9/ACTIONS!D8) -> 0.019547165 | C7: =LN(ACTIONS!E9/ACTIONS!E8) -> -0.011524486 | D7: =LN(ACTIONS!F9/ACTIONS!F8) -> -0.0058553074 | E7: =LN(ACTIONS!G9/ACTIONS!G8) -> -0.016960615 | F7: =LN(ACTIONS!H9/ACTIONS!H8) -> -0.0040584471 | G7: =LN(ACTIONS!I9/ACTIONS!I8) -> -0.0055941611 | H7: =LN(ACTIONS!J9/ACTIONS!J8) -> -0.026296122 | I7: =LN(ACTIONS!K9/ACTIONS!K8) -> 0.0045303139 | ... K7: =LN(ACTIONS!M9/ACTIONS!M8) -> -0.0021156566 | L7: =LN(INDICE!D9/INDICE!D8) -> 0.00046884632
A8: 41285 | B8: =LN(ACTIONS!D10/ACTIONS!D9) -> 0.010018817 | C8: =LN(ACTIONS!E10/ACTIONS!E9) -> -0.0035987659 | D8: =LN(ACTIONS!F10/ACTIONS!F9) -> 0.00027960297 | E8: =LN(ACTIONS!G10/ACTIONS!G9) -> 0.0065574005 | F8: =LN(ACTIONS!H10/ACTIONS!H9) -> -0.0044833986 | G8: =LN(ACTIONS!I10/ACTIONS!I9) -> -0.00055742397 | H8: =LN(ACTIONS!J10/ACTIONS!J9) -> -0.0092871468 | I8: =LN(ACTIONS!K10/ACTIONS!K9) -> 0.011827428 | ... K8: =LN(ACTIONS!M10/ACTIONS!M9) -> 0.0059827734 | L8: =LN(INDICE!D10/INDICE!D9) -> 0.0032839516
A9: 41288 | B9: =LN(ACTIONS!D11/ACTIONS!D10) -> 0.011312897 | C9: =LN(ACTIONS!E11/ACTIONS!E10) -> 0.011589553 | D9: =LN(ACTIONS!F11/ACTIONS!F10) -> -0.00027960297 | E9: =LN(ACTIONS!G11/ACTIONS!G10) -> -0.019802627 | F9: =LN(ACTIONS!H11/ACTIONS!H10) -> 0.008946786 | G9: =LN(ACTIONS!I11/ACTIONS!I10) -> 0.0083657715 | H9: =LN(ACTIONS!J11/ACTIONS!J10) -> 0.0021929833 | I9: =LN(ACTIONS!K11/ACTIONS!K10) -> 0.00064159323 | ... K9: =LN(ACTIONS!M11/ACTIONS!M10) -> 0.0066445427 | L9: =LN(INDICE!D11/INDICE!D10) -> -0.0022437668
A10: 41289 | B10: =LN(ACTIONS!D12/ACTIONS!D11) -> -0.028947385 | C10: =LN(ACTIONS!E12/ACTIONS!E11) -> 0.00087866164 | D10: =LN(ACTIONS!F12/ACTIONS!F11) -> 0.0077994824 | E10: =LN(ACTIONS!G12/ACTIONS!G11) -> 0.021108963 | F10: =LN(ACTIONS!H12/ACTIONS!H11) -> 0.0056520134 | G10: =LN(ACTIONS!I12/ACTIONS!I11) -> -0.00166018 | H10: =LN(ACTIONS!J12/ACTIONS!J11) -> -0.0076965746 | I10: =LN(ACTIONS!K12/ACTIONS!K11) -> 0.0024087135 | ... K10: =LN(ACTIONS!M12/ACTIONS!M11) -> 0.0107472 | L10: =LN(INDICE!D12/INDICE!D11) -> 0.0015459911
A11: 41290 | B11: =LN(ACTIONS!D13/ACTIONS!D12) -> -0.011362795 | C11: =LN(ACTIONS!E13/ACTIONS!E12) -> 0 | D11: =LN(ACTIONS!F13/ACTIONS!F12) -> 0.0022172958 | E11: =LN(ACTIONS!G13/ACTIONS!G12) -> 0.015544354 | F11: =LN(ACTIONS!H13/ACTIONS!H12) -> -0.047824447 | G11: =LN(ACTIONS!I13/ACTIONS!I12) -> 0.017132608 | H11: =LN(ACTIONS!J13/ACTIONS!J12) -> -0.002763196 | I11: =LN(ACTIONS!K13/ACTIONS!K12) -> -0.032197929 | ... K11: =LN(ACTIONS!M13/ACTIONS!M12) -> -0.0055325176 | L11: =LN(INDICE!D13/INDICE!D12) -> -0.00218144
A12: 41291 | B12: =LN(ACTIONS!D14/ACTIONS!D13) -> 0.010519269 | C12: =LN(ACTIONS!E14/ACTIONS!E13) -> 0.0061762919 | D12: =LN(ACTIONS!F14/ACTIONS!F13) -> 0.010191522 | E12: =LN(ACTIONS!G14/ACTIONS!G13) -> 0.03162819 | F12: =LN(ACTIONS!H14/ACTIONS!H13) -> -0.0021137188 | G12: =LN(ACTIONS!I14/ACTIONS!I13) -> 0.0082055079 | H12: =LN(ACTIONS!J14/ACTIONS!J13) -> -0.00055355662 | I12: =LN(ACTIONS!K14/ACTIONS!K13) -> -0.0010578094 | ... K12: =LN(ACTIONS!M14/ACTIONS!M13) -> -0.011508409 | L12: =LN(INDICE!D14/INDICE!D13) -> 0.0046386503
A13: 41292 | B13: =LN(ACTIONS!D15/ACTIONS!D14) -> 0.014049922 | C13: =LN(ACTIONS!E15/ACTIONS!E14) -> 0.0026387104 | D13: =LN(ACTIONS!F15/ACTIONS!F14) -> 0.010088702 | E13: =LN(ACTIONS!G15/ACTIONS!G14) -> 0.017896189 | F13: =LN(ACTIONS!H15/ACTIONS!H14) -> 0.0063278001 | G13: =LN(ACTIONS!I15/ACTIONS!I14) -> 0.00269634 | H13: =LN(ACTIONS!J15/ACTIONS!J14) -> 0.0038684768 | I13: =LN(ACTIONS!K15/ACTIONS!K14) -> 0 | ... K13: =LN(ACTIONS!M15/ACTIONS!M14) -> -0.043734568 | L13: =LN(INDICE!D15/INDICE!D14) -> 0.0035892303
A14: 41295 | B14: =LN(ACTIONS!D16/ACTIONS!D15) -> 0.022326764 | C14: =LN(ACTIONS!E16/ACTIONS!E15) -> 0.028529628 | D14: =LN(ACTIONS!F16/ACTIONS!F15) -> -0.012832941 | E14: =LN(ACTIONS!G16/ACTIONS!G15) -> -0.0036764747 | F14: =LN(ACTIONS!H16/ACTIONS!H15) -> 0.0067058089 | G14: =LN(ACTIONS!I16/ACTIONS!I15) -> 0.0037984708 | H14: =LN(ACTIONS!J16/ACTIONS!J15) -> 0.0016533484 | I14: =LN(ACTIONS!K16/ACTIONS!K15) -> 0.013456182 | ... K14: =LN(ACTIONS!M16/ACTIONS!M15) -> -0.014765864 | L14: =LN(INDICE!D16/INDICE!D15) -> 0.0043079369
A15: 41296 | B15: =LN(ACTIONS!D17/ACTIONS!D16) -> -0.010963946 | C15: =LN(ACTIONS!E17/ACTIONS!E16) -> -0.016322376 | D15: =LN(ACTIONS!F17/ACTIONS!F16) -> 0.0090275541 | E15: =LN(ACTIONS!G17/ACTIONS!G16) -> 0.010381773 | F15: =LN(ACTIONS!H17/ACTIONS!H16) -> -0.0025094116 | G15: =LN(ACTIONS!I17/ACTIONS!I16) -> 0.0016082058 | H15: =LN(ACTIONS!J17/ACTIONS!J16) -> -0.0088496153 | I15: =LN(ACTIONS!K17/ACTIONS!K16) -> -0.0016721538 | ... K15: =LN(ACTIONS!M17/ACTIONS!M16) -> 0.015132232 | L15: =LN(INDICE!D17/INDICE!D16) -> -0.00029287671
A16: 41297 | B16: =LN(ACTIONS!D18/ACTIONS!D17) -> -0.010808233 | C16: =LN(ACTIONS!E18/ACTIONS!E17) -> -0.015719211 | D16: =LN(ACTIONS!F18/ACTIONS!F17) -> 0.015671761 | E16: =LN(ACTIONS!G18/ACTIONS!G17) -> 0.013876542 | F16: =LN(ACTIONS!H18/ACTIONS!H17) -> -0.0012570712 | G16: =LN(ACTIONS!I18/ACTIONS!I17) -> -0.0016082058 | H16: =LN(ACTIONS!J18/ACTIONS!J17) -> -0.014549781 | I16: =LN(ACTIONS!K18/ACTIONS!K17) -> -0.0014392445 | ... K16: =LN(ACTIONS!M18/ACTIONS!M17) -> -0.0010995053 | L16: =LN(INDICE!D18/INDICE!D17) -> 0.0029846162
A17: 41298 | B17: =LN(ACTIONS!D19/ACTIONS!D18) -> 0.016577927 | C17: =LN(ACTIONS!E19/ACTIONS!E18) -> 0.029500115 | D17: =LN(ACTIONS!F19/ACTIONS!F18) -> -0.0026845654 | E17: =LN(ACTIONS!G19/ACTIONS!G18) -> 0.0035885206 | F17: =LN(ACTIONS!H19/ACTIONS!H18) -> 0.0020942416 | G17: =LN(ACTIONS!I19/ACTIONS!I18) -> 0.0043184278 | H17: =LN(ACTIONS!J19/ACTIONS!J18) -> 0.016769538 | I17: =LN(ACTIONS!K19/ACTIONS!K18) -> 0.012672396 | ... K17: =LN(ACTIONS!M19/ACTIONS!M18) -> 0.0080351053 | L17: =LN(INDICE!D19/INDICE!D18) -> 0.010795648
... A2533: 44925 | B2533: =LN(ACTIONS!D2535/ACTIONS!D2534) -> -0.010129518 | C2533: =LN(ACTIONS!E2535/ACTIONS!E2534) -> -0.0065509569 | D2533: =LN(ACTIONS!F2535/ACTIONS!F2534) -> -0.0049193868 | E2533: =LN(ACTIONS!G2535/ACTIONS!G2534) -> -0.010415117 | F2533: =LN(ACTIONS!H2535/ACTIONS!H2534) -> -0.0024113829 | G2533: =LN(ACTIONS!I2535/ACTIONS!I2534) -> 0.0080797639 | H2533: =LN(ACTIONS!J2535/ACTIONS!J2534) -> -0.019493795 | I2533: =LN(ACTIONS!K2535/ACTIONS!K2534) -> -0.010624031 | ... K2533: =LN(ACTIONS!M2535/ACTIONS!M2534) -> -0.0063331434 | L2533: =LN(INDICE!D2535/INDICE!D2534) -> -0.0081500218

Sheet Markowitz
B1: E(Ri) = | D1: Ω : | E1: NATWEST GROUP | F1: PHOENIX GROUP HDG. | G1: DIAGEO | H1: ASSOCIATED BRIT.FOODS | I1: IMPERIAL BRANDS | J1: ROLLS-ROYCE HOLDINGS | K1: RENTOKIL INITIAL | L1: GLENCORE | M1: BARRATT DEVELOPMENTS | N1: KINGFISHER
A2: NATWEST GROUP | B2: -9.200508e-05 | E2: 0.00048382877 | F2: 0.00016962226 | G2: 5.5152103e-05 | H2: 0.0001467513 | I2: 6.2584515e-05 | J2: 0.00022883289 | K2: 4.4202307e-05 | L2: 0.00023581485 | M2: 0.00023383299 | N2: 0.00015508009
A3: PHOENIX GROUP HDG. | B3: 0.00015027243 | E3: 0.00016962226 | F3: 0.00024981307 | G3: 7.041386e-05 | H3: 0.00011375109 | I3: 5.9712369e-05 | J3: 0.00016165711 | K3: 6.64631e-05 | L3: 0.00015342782 | M3: 0.0001755056 | N3: 0.00010406474
A4: DIAGEO | B4: 0.00027801762 | E4: 5.5152103e-05 | F4: 7.041386e-05 | G4: 0.00016656711 | H4: 8.7685467e-05 | I4: 7.2902331e-05 | J4: 0.00012374564 | K4: 8.1423832e-05 | L4: 8.4391443e-05 | M4: 8.3149227e-05 | N4: 5.1541185e-05
A5: ASSOCIATED BRIT.FOODS | B5: 7.6001889e-07 | E5: 0.0001467513 | F5: 0.00011375109 | G5: 8.7685467e-05 | H5: 0.00031052747 | I5: 7.2949789e-05 | J5: 0.00019472248 | K5: 5.882e-05 | L5: 0.00011583401 | M5: 0.00017459921 | N5: 0.00010994622
A6: IMPERIAL BRANDS | B6: -6.079964e-05 | E6: 6.2584515e-05 | F6: 5.9712369e-05 | G6: 7.2902331e-05 | H6: 7.2949789e-05 | I6: 0.00022194717 | J6: 9.5400653e-05 | K6: 4.2264239e-05 | L6: 8.1320891e-05 | M6: 6.1118001e-05 | N6: 5.1600343e-05
A7: ROLLS-ROYCE HOLDINGS | B7: -0.00043233993 | E7: 0.00022883289 | F7: 0.00016165711 | G7: 0.00012374564 | H7: 0.00019472248 | I7: 9.5400653e-05 | J7: 0.00083254708 | K7: 6.3261819e-05 | L7: 0.00025987309 | M7: 0.00020753479 | N7: 0.00012240329
A8: RENTOKIL INITIAL | B8: 0.00066169447 | E8: 4.4202307e-05 | F8: 6.64631e-05 | G8: 8.1423832e-05 | H8: 5.882e-05 | I8: 4.2264239e-05 | J8: 6.3261819e-05 | K8: 0.00023319632 | L8: 8.4345088e-05 | M8: 0.00010445555 | N8: 5.8288832e-05
A9: GLENCORE | B9: 0.00015386824 | E9: 0.00023581485 | F9: 0.00015342782 | G9: 8.4391443e-05 | H9: 0.00011583401 | I9: 8.1320891e-05 | J9: 0.00025987309 | K9: 8.4345088e-05 | L9: 0.00076842288 | M9: 0.0001493677 | N9: 0.00011370713
A10: BARRATT DEVELOPMENTS | B10: 0.00025515108 | E10: 0.00023383299 | F10: 0.0001755056 | G10: 8.3149227e-05 | H10: 0.00017459921 | I10: 6.1118001e-05 | J10: 0.00020753479 | K10: 0.00010445555 | L10: 0.0001493677 | M10: 0.00053436684 | N10: 0.00017024525
A11: KINGFISHER | B11: -7.6898591e-05 | E11: 0.00015508009 | F11: 0.00010406474 | G11: 5.1541185e-05 | H11: 0.00010994622 | I11: 5.1600343e-05 | J11: 0.00012240329 | K11: 5.8288832e-05 | L11: 0.00011370713 | M11: 0.00017024525 | N11: 0.00036849898
B13: 1000000 | C13: X : | G13: PMin | H13: P1 | I13: P2 | J13: P3
A14: E(RP) = | B14: 0.0016709528 | C14: NATWEST GROUP | D14: -0.15306609 | E14: -153066.09 | G14: 0.050873829 | H14: 0.049478575 | I14: 0.048083322 | J14: 0.046688068
A15: σ(RP) = | B15: 0.031812566 | C15: PHOENIX GROUP HDG. | D15: 0.21222967 | E15: 212229.67 | G15: 0.13576399 | H15: 0.13628713 | I15: 0.13681027 | J15: 0.13733341
C16: DIAGEO | D16: 0.71289017 | E16: 712890.17 | G16: 0.27290981 | H16: 0.27591993 | I16: 0.27893005 | J16: 0.28194018
C17: ASSOCIATED BRIT.FOODS | D17: -0.18549291 | E17: -185492.91 | G17: 0.069242859 | H17: 0.067500086 | I17: 0.065757312 | J17: 0.064014539
C18: IMPERIAL BRANDS | D18: -0.61262229 | E18: -612622.29 | G18: 0.22900674 | H18: 0.22324874 | I18: 0.21749074 | J18: 0.21173274
C19: ROLLS-ROYCE HOLDINGS | D19: -0.5148194 | E19: -514819.4 | G19: -0.028215708 | H19: -0.031544804 | I19: -0.034873901 | J19: -0.038202997
C20: RENTOKIL INITIAL | D20: 1.5998332 | E20: 1599833.2 | G20: 0.20956808 | H20: 0.21907957 | I20: 0.22859106 | J20: 0.23810255
C21: GLENCORE | D21: 0.11143384 | E21: 111433.84 | G21: -0.0036948677 | H21: -0.0029072153 | I21: -0.0021195628 | J21: -0.0013319104
C22: BARRATT DEVELOPMENTS | D22: 0.23565455 | E22: 235654.55 | G22: -0.041490069 | H22: -0.039593985 | I22: -0.037697902 | J22: -0.035801818
C23: KINGFISHER | D23: -0.40604073 | E23: -406040.73 | G23: 0.10603534 | H23: 0.10253197 | I23: 0.099028606 | J23: 0.09552524
C24: Contrainte : | D24: 1 | F24: E(RP) = | G24: 0.00020928386 | H24: 0.00021928386 | I24: 0.00022928386 | J24: 0.00023928386
D25: 0.031812566 | F25: σ(RP) = | G25: 0.0097911057 | H25: 0.0097932954 | I25: 0.0097998613 | J25: 0.0098107948
E26: 0.10091875 | F26: 1e-05
F27: Méthode de MERTON : | H27: x% de P1 : | I27: -0.5
H28: (1-x%) de P2 : | I28: 1.5
H29: cov(RP1,RP2) | I29: 9.5951517e-05
H30: rho(RP1,RP2) | I30: 0.99977682
A31: RF : | B31: 0.014197445 | C31: 5.6339066e-05
A32: P : X% dans PM et (1-x)% dans RF | C32: 1000000 | D32: E(Rp)=RF+Pente*σ(RP) | G32: P1 | H32: 100918.75
A33: E(RP1) = | B33: 0.00021928386 | C33: x% de PM : | D33: 0.10091875 | E33: NATWEST GROUP | F33: -0.15306609 | G33: -0.015447238 | H33: -15447.238
A34: σ(RP1) = | B34: 0.0032104844 | C34: (1-x%) de RF : | D34: 0.89908125 | E34: PHOENIX GROUP HDG. | F34: 0.21222967 | G34: 0.021417953 | H34: 21417.953
D35: 1 | E35: DIAGEO | F35: 0.71289017 | G35: 0.071943984 | H35: 71943.984
A36: E(RPM) = | B36: 0.0016709528 | E36: ASSOCIATED BRIT.FOODS | F36: -0.18549291 | G36: -0.018719712 | H36: -18719.712
A37: σ(RPM) = | B37: 0.031812566 | E37: IMPERIAL BRANDS | F37: -0.61262229 | G37: -0.061825075 | H37: -61825.075
A38: Pente : | B38: 0.050753959 | D38: 100918.75 | E38: ROLLS-ROYCE HOLDINGS | F38: -0.5148194 | G38: -0.05195493 | H38: -51954.93
D39: 899081.25 | E39: RENTOKIL INITIAL | F39: 1.5998332 | G39: 0.16145316 | H39: 161453.16
E40: GLENCORE | F40: 0.11143384 | G40: 0.011245764 | H40: 11245.764
E41: BARRATT DEVELOPMENTS | F41: 0.23565455 | G41: 0.023781962 | H41: 23781.962
...

Sheet Sharpe
A1: V(RM) : | B1: 0.00010112544
B3: NATWEST GROUP | C3: PHOENIX GROUP HDG. | D3: DIAGEO | E3: ASSOCIATED BRIT.FOODS | F3: IMPERIAL BRANDS | G3: ROLLS-ROYCE HOLDINGS | H3: RENTOKIL INITIAL | I3: GLENCORE | J3: BARRATT DEVELOPMENTS | K3: KINGFISHER
A4: βi : | B4: 1.2174493 | C4: 0.95333826 | D4: 0.83442832 | E4: 0.935823 | F4: 0.70681933 | G4: 1.4261094 | H4: 0.713025 | I4: 1.6878163 | J4: 1.1641894 | K4: 0.81333328
A5: αi : | B5: -0.00019341665 | C5: 7.0860894e-05 | D5: 0.00020851109 | E5: -7.7192528e-05 | F5: -0.00011967655 | G5: -0.00055113254 | H5: 0.00060230064 | I5: 1.3275867e-05 | J5: 0.00015817597 | K5: -0.00014464794
A6: E(Ri) : | B6: -9.200508e-05 | C6: 0.00015027243 | D6: 0.00027801762 | E6: 7.6001889e-07 | F6: -6.079964e-05 | G6: -0.00043233993 | H6: 0.00066169447 | I6: 0.00015386824 | J6: 0.00025515108 | K6: -7.6898591e-05
A7: v(Ri) : | B7: 0.00048382877 | C7: 0.00024981307 | D7: 0.00016656711 | E7: 0.00031052747 | F7: 0.00022194717 | G7: 0.00083254708 | H7: 0.00023319632 | I7: 0.00076842288 | J7: 0.00053436684 | K7: 0.00036849898
A8: σ(Ri) = | B8: 0.021996108 | C8: 0.015805476 | D8: 0.012906088 | E8: 0.01762179 | F8: 0.014897891 | G8: 0.028853892 | H8: 0.015270767 | I8: 0.027720442 | J8: 0.023116376 | K8: 0.019196327
A9: β2i*V(RM) : | B9: 0.00014988641 | C9: 9.1908249e-05 | D9: 7.0410677e-05 | E9: 8.8562094e-05 | F9: 5.0521621e-05 | G9: 0.00020566771 | H9: 5.1412647e-05 | I9: 0.00028807845 | J9: 0.00013705906 | K9: 6.6895596e-05
A10: V(ei)= | B10: 0.00033407567 | C10: 0.00015796786 | D10: 9.6194823e-05 | E10: 0.00022205398 | F10: 0.00017149398 | G10: 0.00062712962 | H10: 0.00018185624 | I10: 0.00048053618 | J10: 0.00039746639 | K10: 0.00030172378
A12: cov(Ri,Rj) estimée | B12: 0.0001424212 | C12: Cov histo. | D12: 8.4391443e-05
A13: corrélation : | B13: 0.39808872
B15: NATWEST GROUP | C15: PHOENIX GROUP HDG. | D15: DIAGEO | E15: ASSOCIATED BRIT.FOODS | F15: IMPERIAL BRANDS | G15: ROLLS-ROYCE HOLDINGS | H15: RENTOKIL INITIAL | I15: GLENCORE | J15: BARRATT DEVELOPMENTS | K15: KINGFISHER
A16: NATWEST GROUP | B16: 0.00014988641 | C16: 0.00011737034 | D16: 0.00010273073 | E16: 0.00011521395 | F16: 8.7020137e-05 | G16: 0.00017557561 | H16: 8.7784149e-05 | I16: 0.00020779568 | J16: 0.0001433293 | K16: 0.00010013361
A17: PHOENIX GROUP HDG. | B17: 0.00011737034 | C17: 9.1908249e-05 | D17: 8.0444527e-05 | E17: 9.0219659e-05 | F17: 6.8142158e-05 | G17: 0.00013748658 | H17: 6.8740427e-05 | I17: 0.00016271689 | J17: 0.00011223573 | K17: 7.8410823e-05
A18: DIAGEO | B18: 0.00010273073 | C18: 8.0444527e-05 | D18: 7.0410677e-05 | E18: 7.8966556e-05 | F18: 5.9642783e-05 | G18: 0.00012033787 | H18: 6.016643e-05 | I18: 0.0001424212 | J18: 9.8236556e-05 | K18: 6.8630636e-05
A19: ASSOCIATED BRIT.FOODS | B19: 0.00011521395 | C19: 9.0219659e-05 | D19: 7.8966556e-05 | E19: 8.8562094e-05 | F19: 6.6890212e-05 | G19: 0.0001349606 | H19: 6.747749e-05 | I19: 0.00015972736 | J19: 0.00011017367 | K19: 7.6970216e-05
A20: IMPERIAL BRANDS | B20: 8.7020137e-05 | C20: 6.8142158e-05 | D20: 5.9642783e-05 | E20: 6.6890212e-05 | F20: 5.0521621e-05 | G20: 0.00010193462 | H20: 5.0965187e-05 | I20: 0.00012064075 | J20: 8.3213255e-05 | K20: 5.8134963e-05
A21: ROLLS-ROYCE HOLDINGS | B21: 0.00017557561 | C21: 0.00013748658 | D21: 0.00012033787 | E21: 0.0001349606 | F21: 0.00010193462 | G21: 0.00020566771 | H21: 0.00010282957 | I21: 0.00024341002 | J21: 0.00016789468 | K21: 0.00011729563
A22: RENTOKIL INITIAL | B22: 8.7784149e-05 | C22: 6.8740427e-05 | D22: 6.016643e-05 | E22: 6.747749e-05 | F22: 5.0965187e-05 | G22: 0.00010282957 | H22: 5.1412647e-05 | I22: 0.00012169994 | J22: 8.3943844e-05 | K22: 5.8645372e-05
A23: GLENCORE | B23: 0.00020779568 | C23: 0.00016271689 | D23: 0.0001424212 | E23: 0.00015972736 | F23: 0.00012064075 | G23: 0.00024341002 | H23: 0.00012169994 | I23: 0.00028807845 | J23: 0.00019870521 | K23: 0.00013882068
A24: BARRATT DEVELOPMENTS | B24: 0.0001433293 | C24: 0.00011223573 | D24: 9.8236556e-05 | E24: 0.00011017367 | F24: 8.3213255e-05 | G24: 0.00016789468 | H24: 8.3943844e-05 | I24: 0.00019870521 | J24: 0.00013705906 | K24: 9.5753054e-05
A25: KINGFISHER | B25: 0.00010013361 | C25: 7.8410823e-05 | D25: 6.8630636e-05 | E25: 7.6970216e-05 | F25: 5.8134963e-05 | G25: 0.00011729563 | H25: 5.8645372e-05 | I25: 0.00013882068 | J25: 9.5753054e-05 | K25: 6.6895596e-05
A27: Matrice de Sharpe | B27: NATWEST GROUP | C27: PHOENIX GROUP HDG. | D27: DIAGEO | E27: ASSOCIATED BRIT.FOODS | F27: IMPERIAL BRANDS | G27: ROLLS-ROYCE HOLDINGS | H27: RENTOKIL INITIAL | I27: GLENCORE | J27: BARRATT DEVELOPMENTS | K27: KINGFISHER
A28: NATWEST GROUP | B28: 0.00048382877 | C28: 0.00011737034 | D28: 0.00010273073 | E28: 0.00011521395 | F28: 8.7020137e-05 | G28: 0.00017557561 | H28: 8.7784149e-05 | I28: 0.00020779568 | J28: 0.0001433293 | K28: 0.00010013361
A29: PHOENIX GROUP HDG. | B29: 0.00011737034 | C29: 0.00024981307 | D29: 8.0444527e-05 | E29: 9.0219659e-05 | F29: 6.8142158e-05 | G29: 0.00013748658 | H29: 6.8740427e-05 | I29: 0.00016271689 | J29: 0.00011223573 | K29: 7.8410823e-05
A30: DIAGEO | B30: 0.00010273073 | C30: 8.0444527e-05 | D30: 0.00016656711 | E30: 7.8966556e-05 | F30: 5.9642783e-05 | G30: 0.00012033787 | H30: 6.016643e-05 | I30: 0.0001424212 | J30: 9.8236556e-05 | K30: 6.8630636e-05
A31: ASSOCIATED BRIT.FOODS | B31: 0.00011521395 | C31: 9.0219659e-05 | D31: 7.8966556e-05 | E31: 0.00031052747 | F31: 6.6890212e-05 | G31: 0.0001349606 | H31: 6.747749e-05 | I31: 0.00015972736 | J31: 0.00011017367 | K31: 7.6970216e-05
A32: IMPERIAL BRANDS | B32: 8.7020137e-05 | C32: 6.8142158e-05 | D32: 5.9642783e-05 | E32: 6.6890212e-05 | F32: 0.00022194717 | G32: 0.00010193462 | H32: 5.0965187e-05 | I32: 0.00012064075 | J32: 8.3213255e-05 | K32: 5.8134963e-05
A33: ROLLS-ROYCE HOLDINGS | B33: 0.00017557561 | C33: 0.00013748658 | D33: 0.00012033787 | E33: 0.0001349606 | F33: 0.00010193462 | G33: 0.00083254708 | H33: 0.00010282957 | I33: 0.00024341002 | J33: 0.00016789468 | K33: 0.00011729563
A34: RENTOKIL INITIAL | B34: 8.7784149e-05 | C34: 6.8740427e-05 | D34: 6.016643e-05 | E34: 6.747749e-05 | F34: 5.0965187e-05 | G34: 0.00010282957 | H34: 0.00023319632 | I34: 0.00012169994 | J34: 8.3943844e-05 | K34: 5.8645372e-05
A35: GLENCORE | B35: 0.00020779568 | C35: 0.00016271689 | D35: 0.0001424212 | E35: 0.00015972736 | F35: 0.00012064075 | G35: 0.00024341002 | H35: 0.00012169994 | I35: 0.00076842288 | J35: 0.00019870521 | K35: 0.00013882068
A36: BARRATT DEVELOPMENTS | B36: 0.0001433293 | C36: 0.00011223573 | D36: 9.8236556e-05 | E36: 0.00011017367 | F36: 8.3213255e-05 | G36: 0.00016789468 | H36: 8.3943844e-05 | I36: 0.00019870521 | J36: 0.00053436684 | K36: 9.5753054e-05
A37: KINGFISHER | B37: 0.00010013361 | C37: 7.8410823e-05 | D37: 6.8630636e-05 | E37: 7.6970216e-05 | F37: 5.8134963e-05 | G37: 0.00011729563 | H37: 5.8645372e-05 | I37: 0.00013882068 | J37: 9.5753054e-05 | K37: 0.00036849898
B40: 1000000 | C40: X pour Pmin :
A41: E(RPMin) = | B41: 0.0002253695 | C41: NATWEST GROUP | D41: 0.0030723045
A42: σ(RPMin) = | B42: 0.009563309 | C42: PHOENIX GROUP HDG. | D42: 0.1307362
C43: DIAGEO | D43: 0.30654617
C44: ASSOCIATED BRIT.FOODS | D44: 0.09886629
C45: IMPERIAL BRANDS | D45: 0.22724183
C46: ROLLS-ROYCE HOLDINGS | D46: -0.02308751
...

Sheet Regression DIAGEO
A1: RAPPORT DÉTAILLÉ
A3: Statistiques de la régression
A4: Coefficient de détermination multiple | B4: 0.65016656
A5: Coefficient de détermination R^2 | B5: 0.42271656
A6: Coefficient de détermination R^2 | B6: 0.4224861
A7: Erreur-type | B7: 0.0098078959
A8: Observations | B8: 2507
A10: ANALYSE DE VARIANCE
E11: F | F11: Valeur critique de F
A12: Régression | B12: 1 | C12: 0.17644916 | D12: 0.17644916 | E12: 1834.2895 | F12: 0
A13: Résidus | B13: 2505 | C13: 0.24096803 | D13: 9.6194823e-05
A14: Total | B14: 2506 | C14: 0.41741719
B16: Coefficients | C16: Erreur-type | D16: Statistique t | E16: Probabilité | F16: Limite inférieure pour seuil de confiance = 95% | G16: Limite supérieure pour seuil de confiance = 95% | H16: Limite inférieure pour seuil de confiance = 95,0% | I16: Limite supérieure pour seuil de confiance = 95,0%
A17: Constante | B17: 0.00020851109 | C17: 0.0001958906 | D17: 1.0644262 | E17: 0.28713566 | F17: -0.00017543448 | G17: 0.00059245665 | H17: -0.00017543448 | I17: 0.00059245665
A18: FTSE 100 | B18: 0.83442832 | C18: 0.019482967 | D18: 42.828606 | E18: 0 | F18: 0.79624171 | G18: 0.87261494 | H18: 0.79624171 | I18: 0.87261494
A22: ANALYSE DES RÉSIDUS
A23: Observation | B23: Prédiction DIAGEO | C23: Résidus
A24: 1 | B24: 0.0060522653 | C24: -0.0024832842
A25: 2 | B25: -0.0032598057 | C25: -0.0030632394
A26: 3 | B26: -0.0012994662 | C26: -0.0033999205
A27: 4 | B27: 0.0063910768 | C27: -0.0097216378
A28: 5 | B28: 0.00059972973 | C28: -0.0064550371
A29: 6 | B29: 0.0029487333 | C29: -0.0026691303
A30: 7 | B30: -0.0016637515 | C30: 0.0013841485
A31: 8 | B31: 0.0014985298 | C31: 0.0063009526
A32: 9 | B32: -0.0016117442 | C32: 0.00382904
A33: 10 | B33: 0.0040791322 | C33: 0.0061123897
A34: 11 | B34: 0.0032034665 | C34: 0.0068852353
A35: 12 | B35: 0.0038031757 | C35: -0.016636116
... A2530: 2507 | B2530: -0.0065920979 | C2530: 0.0016727111

Sheet Regression GLENCORE
A1: RAPPORT DÉTAILLÉ
A3: Statistiques de la régression
A4: Coefficient de détermination multiple | B4: 0.61228729
A5: Coefficient de détermination R^2 | B5: 0.37489573
A6: Coefficient de détermination R^2 | B6: 0.37464619
A7: Erreur-type | B7: 0.021921135
A8: Observations | B8: 2507
A10: ANALYSE DE VARIANCE
E11: F | F11: Valeur critique de F
A12: Régression | B12: 1 | C12: 0.72192461 | D12: 0.72192461 | E12: 1502.3314 | F12: 0
A13: Résidus | B13: 2505 | C13: 1.2037431 | D13: 0.00048053618
A14: Total | B14: 2506 | C14: 1.9256677
B16: Coefficients | C16: Erreur-type | D16: Statistique t | E16: Probabilité | F16: Limite inférieure pour seuil de confiance = 95% | G16: Limite supérieure pour seuil de confiance = 95% | H16: Limite inférieure pour seuil de confiance = 95,0% | I16: Limite supérieure pour seuil de confiance = 95,0%
A17: Constante | B17: 1.3275867e-05 | C17: 0.00043782523 | D17: 0.030322297 | E17: 0.97581001 | F17: -0.00084486158 | G17: 0.00087141331 | H17: -0.00084486158 | I17: 0.00087141331
A18: FTSE 100 | B18: 1.6878163 | C18: 0.0435454 | D18: 38.759921 | E18: 0 | F18: 1.6024673 | G18: 1.7731652 | H18: 1.6024673 | I18: 1.7731652
A22: ANALYSE DES RÉSIDUS
A23: Observation | B23: Prédiction GLENCORE | C23: Résidus
A24: 1 | B24: 0.011833564 | C24: -0.0031387794
A25: 2 | B25: -0.0070021638 | C25: 0.0042534571
A26: 3 | B26: -0.0030369425 | C26: -0.0043745327
A27: 4 | B27: 0.012518886 | C27: 0.0090049058
A28: 5 | B28: 0.00080460231 | C28: 0.0037257116
A29: 6 | B29: 0.0055559828 | C29: 0.0062714457
A30: 7 | B30: -0.0037737902 | C30: 0.0044153835
A31: 8 | B31: 0.0026226247 | C31: -0.00021391122
A32: 9 | B32: -0.003668594 | C32: -0.028529335
A33: 10 | B33: 0.0078424652 | C33: -0.0089002746
A34: 11 | B34: 0.0060712372 | C34: -0.0060712372
A35: 12 | B35: 0.0072842819 | C35: 0.0061719001
... A2530: 2507 | B2530: -0.013742463 | C2530: 0.0031184327

Sheet Performances
A1: SUIVI DE PERFORMANCES — Projet MEAFGP 2025-2026
A2: Deux portefeuilles retenus : PMin Markowitz (approche moyenne-variance) et PMin Sharpe (modèle de Sharpe)
A3: Consigne : choisir un portefeuille par approche, calculer les performances historiques et suivre mars 2026.
A5: A. COMPOSITION DES PORTEFEUILLES
A6: Titre | B6: Poids PMin Markowitz | C6: Poids PMin Sharpe | D6: E(Ri) annualisé
A7: NATWEST GROUP | B7: 0.050874 | C7: 0.003072 | D7: -0.023185
A8: PHOENIX GROUP HDG. | B8: 0.135764 | C8: 0.130736 | D8: 0.037869
A9: DIAGEO | B9: 0.27291 | C9: 0.306546 | D9: 0.07006
A10: ASSOCIATED BRIT.FOODS | B10: 0.069243 | C10: 0.098866 | D10: 0.000192
A11: IMPERIAL BRANDS
A12: ROLLS-ROYCE HOLDINGS | B12: -0.028216 | C12: -0.023088 | D12: -0.10895
A13: RENTOKIL INITIAL | B13: 0.209568 | C13: 0.211758 | D13: 0.166747
A14: GLENCORE | B14: -0.003695 | C14: -0.0706 | D14: 0.038775
A15: BARRATT DEVELOPMENTS | B15: -0.04149 | C15: 0.01254 | D15: 0.064298
A16: KINGFISHER | B16: 0.106035 | C16: 0.102928 | D16: -0.019378
A17: Somme | B17: 1 | C17: 1
A19: Justification : | B19: PMin Markowitz = variance minimale (Omega historique journalier). PMin Sharpe = variance minimale (modèle de marché via Sharpe). Les deux minimisent le risque selon leur approche respective.
A21: B. PERFORMANCES HISTORIQUES 2013–2022
A22: Indicateur | B22: PMin Markowitz | C22: PMin Sharpe | D22: FTSE 100 (benchmark)
A23: Rendement annualisé E(Rp) | B23: 0.05274 | C23: 0.056793 | D23: 0.020991
A24: Volatilité annualisée σ(Rp) | B24: 0.155429 | C24: 0.159738 | D24: 0.159636
A25: Ratio de Sharpe
A26: Drawdown maximum | B26: -0.360532 | C26: -0.32475 | D26: -0.384928
A27: Rendement total cumulé | B27: 0.498126 | C27: 0.54934 | D27: 0.084708
A29: C. VALEUR LIQUIDATIVE BASE 100 — Historique 2013–2022 (tous les 10 jours)
A30: Date | B30: PMin Markowitz | C30: PMin Sharpe | D30: FTSE 100
A31: 41278 | B31: 100 | C31: 100 | D31: 100
A32: 41292 | B32: 98.4711 | C32: 98.5978 | D32: 101.3974
A33: 41306 | B33: 100.671 | C33: 100.8172 | D33: 103.7725
A34: 41320 | B34: 101.1121 | C34: 101.6898 | D34: 104.5705
A35: 41334 | B35: 103.1868 | C35: 104.6771 | D35: 105.0855
A36: 41348 | B36: 102.9886 | C36: 104.9185 | D36: 107.852
A37: 41366 | B37: 104.6863 | C37: 108.7071 | D37: 105.9003
A38: 41380 | B38: 102.2847 | C38: 106.9637 | D38: 104.7271
A39: 41394 | B39: 102.191 | C39: 107.1714 | D39: 106.5834
A40: 41409 | B40: 103.7447 | C40: 108.4907 | D40: 110.3327
A41: 41424 | B41: 102.9782 | C41: 107.3689 | D41: 109.2902
A42: 41439 | B42: 101.0974 | C42: 105.3113 | D42: 103.9152
... A282: 44925 | B282: 149.8126 | C282: 154.934 | D282: 108.4708
A285: D. SUIVI DE PERFORMANCE — MARS 2026
...
